<?xml version="1.0" ?>
<!-- =================================================================================== -->
<!-- |    This document was autogenerated by xacro from /home/wangdak/catkin_ws/src/robot_description/urdf/robot.urdf.xacro | -->
<!-- |    EDITING THIS FILE BY HAND IS NOT RECOMMENDED                                 | -->
<!-- =================================================================================== -->
<robot name="dakebot">
    <material name="black">
        <color rgba="0.0 0.0 0.0 1.0" />
    </material>
    <!--base_footprint_link-->
    <link name="base_footprint">
        <visual>
            <geometry>
                <sphere radius="0.001" />
            </geometry>
        </visual>
    </link>
    <!--robot_base_link-->
    <link name="robot_base_link">
        <visual>
            <geometry>
                <box size="0.448 0.3 0.12" />
            </geometry>
            <origin rpy="0 0 0" xyz="0 0 0" />
            <material name="yellow">
                <color rgba="1.0 0.5 0.2 1.0" />
            </material>
        </visual>
        <collision>
            <geometry>
                <box size="0.448 0.3 0.12" />
            </geometry>
            <origin rpy="0 0 0" xyz="0 0 0" />
        </collision>
        <inertial>
            <mass value="5" />
            <inertia ixx="0.08962666666666667" ixy="0" ixz="0" iyy="0.12112666666666667" iyz="0" izz="0.043500000000000004" />
            <origin xyz="0 0 0" rpy="0 0 0" />
        </inertial>
    </link>
    <gazebo reference="robot_base_link">
        <material>Gazebo/Yellow</material>
        <plugin name="gazebo_ros_control">
            <robotNamespace>/</robotNamespace>
        </plugin>
    </gazebo>
    <!--base_link joint-->
    <joint name="link2footprint" type="fixed">
        <parent link="base_footprint" />
        <child link="robot_base_link" />
        <origin xyz="0 0 0.11599999999999999" />
    </joint>
    <link name="left_front_wheel">
        <visual>
            <geometry>
                <cylinder length="0.028" radius="0.056" />
            </geometry>
            <origin rpy="1.5705 0.0 0.0" xyz="0.0 0.0 0.0" />
            <material name="black" />
        </visual>
        <collision>
            <geometry>
                <cylinder length="0.028" radius="0.056" />
            </geometry>
            <surface>
                <friction>
                    <fdir1>1 0 0</fdir1>
                    <kp>1000000.0</kp>
                    <!-- kp and kd for rubber -->
                    <kd>100.0</kd>
                    <mu>1</mu>
                    <mu2>1</mu2>
                    <slip1>0.5</slip1>
                    <slip2>0</slip2>
                </friction>
            </surface>
            <origin rpy="1.5705 0.0 0.0" xyz="0.0 0.0 0.0" />
        </collision>
        <inertial>
            <mass value="2" />
            <inertia ixx="0.001698666666666667" ixy="0" ixz="0" iyy="0.001698666666666667" iyz="0" izz="0.0031360000000000003" />
            <origin xyz="0 0 0" rpy="0 0 0" />
        </inertial>
    </link>
    <gazebo reference="left_front_wheel">
        <material>Gazebo/Red</material>
    </gazebo>
    <!--wheels_joint-->
    <joint name="left_front_wheel2robot_base_link" type="continuous">
        <parent link="robot_base_link" />
        <child link="left_front_wheel" />
        <origin xyz="0.112 0.15 -0.06" />
        <axis xyz="0 1 0" />
    </joint>
    <link name="right_front_wheel">
        <visual>
            <geometry>
                <cylinder length="0.028" radius="0.056" />
            </geometry>
            <origin rpy="1.5705 0.0 0.0" xyz="0.0 0.0 0.0" />
            <material name="black" />
        </visual>
        <collision>
            <geometry>
                <cylinder length="0.028" radius="0.056" />
            </geometry>
            <surface>
                <friction>
                    <fdir1>1 0 0</fdir1>
                    <kp>1000000.0</kp>
                    <!-- kp and kd for rubber -->
                    <kd>100.0</kd>
                    <mu>1</mu>
                    <mu2>1</mu2>
                    <slip1>0.5</slip1>
                    <slip2>0</slip2>
                </friction>
            </surface>
            <origin rpy="1.5705 0.0 0.0" xyz="0.0 0.0 0.0" />
        </collision>
        <inertial>
            <mass value="2" />
            <inertia ixx="0.001698666666666667" ixy="0" ixz="0" iyy="0.001698666666666667" iyz="0" izz="0.0031360000000000003" />
            <origin xyz="0 0 0" rpy="0 0 0" />
        </inertial>
    </link>
    <gazebo reference="right_front_wheel">
        <material>Gazebo/Red</material>
    </gazebo>
    <!--wheels_joint-->
    <joint name="right_front_wheel2robot_base_link" type="continuous">
        <parent link="robot_base_link" />
        <child link="right_front_wheel" />
        <origin xyz="0.112 -0.15 -0.06" />
        <axis xyz="0 1 0" />
    </joint>
    <link name="left_rear_wheel">
        <visual>
            <geometry>
                <cylinder length="0.028" radius="0.056" />
            </geometry>
            <origin rpy="1.5705 0.0 0.0" xyz="0.0 0.0 0.0" />
            <material name="black" />
        </visual>
        <collision>
            <geometry>
                <cylinder length="0.028" radius="0.056" />
            </geometry>
            <surface>
                <friction>
                    <fdir1>1 0 0</fdir1>
                    <kp>1000000.0</kp>
                    <!-- kp and kd for rubber -->
                    <kd>100.0</kd>
                    <mu>1</mu>
                    <mu2>1</mu2>
                    <slip1>0.5</slip1>
                    <slip2>0</slip2>
                </friction>
            </surface>
            <origin rpy="1.5705 0.0 0.0" xyz="0.0 0.0 0.0" />
        </collision>
        <inertial>
            <mass value="2" />
            <inertia ixx="0.001698666666666667" ixy="0" ixz="0" iyy="0.001698666666666667" iyz="0" izz="0.0031360000000000003" />
            <origin xyz="0 0 0" rpy="0 0 0" />
        </inertial>
    </link>
    <gazebo reference="left_rear_wheel">
        <material>Gazebo/Red</material>
    </gazebo>
    <!--wheels_joint-->
    <joint name="left_rear_wheel2robot_base_link" type="continuous">
        <parent link="robot_base_link" />
        <child link="left_rear_wheel" />
        <origin xyz="-0.112 0.15 -0.06" />
        <axis xyz="0 1 0" />
    </joint>
    <link name="right_rear_wheel">
        <visual>
            <geometry>
                <cylinder length="0.028" radius="0.056" />
            </geometry>
            <origin rpy="1.5705 0.0 0.0" xyz="0.0 0.0 0.0" />
            <material name="black" />
        </visual>
        <collision>
            <geometry>
                <cylinder length="0.028" radius="0.056" />
            </geometry>
            <surface>
                <friction>
                    <fdir1>1 0 0</fdir1>
                    <kp>1000000.0</kp>
                    <!-- kp and kd for rubber -->
                    <kd>100.0</kd>
                    <mu>1</mu>
                    <mu2>1</mu2>
                    <slip1>0.5</slip1>
                    <slip2>0</slip2>
                </friction>
            </surface>
            <origin rpy="1.5705 0.0 0.0" xyz="0.0 0.0 0.0" />
        </collision>
        <inertial>
            <mass value="2" />
            <inertia ixx="0.001698666666666667" ixy="0" ixz="0" iyy="0.001698666666666667" iyz="0" izz="0.0031360000000000003" />
            <origin xyz="0 0 0" rpy="0 0 0" />
        </inertial>
    </link>
    <gazebo reference="right_rear_wheel">
        <material>Gazebo/Red</material>
    </gazebo>
    <!--wheels_joint-->
    <joint name="right_rear_wheel2robot_base_link" type="continuous">
        <parent link="robot_base_link" />
        <child link="right_rear_wheel" />
        <origin xyz="-0.112 -0.15 -0.06" />
        <axis xyz="0 1 0" />
    </joint>
    <link name="camera">
        <visual>
            <origin rpy="0.0 0.0 0.0" xyz="0.0 0.0 0.0" />
            <geometry>
                <box size="0.01 0.25 0.04" />
            </geometry>
            <material name="yellow">
                <color rgba="1.0 0.5 0.2 1.0" />
            </material>
        </visual>
        <collision>
            <origin rpy="0.0 0.0 0.0" xyz="0.0 0.0 0.0" />
            <geometry>
                <box size="0.01 0.25 0.04" />
            </geometry>
        </collision>
        <inertial>
            <mass value="1.0" />
            <inertia ixx="0.00014166666666666668" ixy="0" ixz="0" iyy="0.005216666666666667" iyz="0" izz="0.005341666666666667" />
            <origin xyz="0 0 0" rpy="0 0 0" />
        </inertial>
    </link>
    <joint name="camera2base" type="fixed">
        <origin rpy="0.0 0.0 0.0" xyz="0.224 0.0 0.0" />
        <parent link="robot_base_link" />
        <child link="camera" />
        <axis xyz="0.0 0.0 0.0" />
        <limit effort="0.0" lower="0.0" upper="0.0" velocity="0.0" />
    </joint>
    <link name="hokuyo">
        <visual>
            <origin rpy="0.0 0.0 0.0" xyz="0.0 0.0 0.0" />
            <geometry>
                <cylinder length="0.032" radius="0.048" />
            </geometry>
            <material name="black" />
        </visual>
        <collision>
            <origin rpy="0.0 0.0 0.0" xyz="0.0 0.0 0.0" />
            <geometry>
                <cylinder length="0.032" radius="0.048" />
            </geometry>
        </collision>
        <inertial>
            <mass value="1.0" />
            <inertia ixx="0.0006613333333333333" ixy="0" ixz="0" iyy="0.0006613333333333333" iyz="0" izz="0.001152" />
            <origin xyz="0 0 0" rpy="0 0 0" />
        </inertial>
    </link>
    <joint name="hokuyo2base" type="fixed">
        <origin rpy="0.0 0.0 0.0" xyz="0.164 0.0 0.08" />
        <parent link="robot_base_link" />
        <child link="hokuyo" />
        <axis xyz="0.0 0.0 0.0" />
        <limit effort="0.0" lower="0.0" upper="0.0" velocity="0.0" />
    </joint>
    <!-- gazebo四轮差速插件 -->
    <gazebo>
        <plugin filename="libgazebo_ros_skid_steer_drive.so" name="skid_steer_drive_controller">
            <updateRate>50</updateRate>
            <robotNamespace>/</robotNamespace>
            <publishOdomTF>true</publishOdomTF>
            <publishWheelTF>false</publishWheelTF>
            <publishTf>1</publishTf>
            <publishWheelJointState>false</publishWheelJointState>
            <leftFrontJoint>left_front_wheel2robot_base_link</leftFrontJoint>
            <rightFrontJoint>right_front_wheel2robot_base_link</rightFrontJoint>
            <leftRearJoint>left_rear_wheel2robot_base_link</leftRearJoint>
            <rightRearJoint>right_rear_wheel2robot_base_link</rightRearJoint>
            <wheelSeparation>0.3</wheelSeparation>
            <wheelDiameter>0.112</wheelDiameter>
            <robotBaseFrame>base_footprint</robotBaseFrame>
            <torque>700</torque>
            <commandTopic>cmd_vel</commandTopic>
            <broadcastTF>true</broadcastTF>
            <odometryFrame>odom</odometryFrame>
            <odometryTopic>odom</odometryTopic>
            <covariance_x>0.000100</covariance_x>
            <covariance_y>0.000100</covariance_y>
            <covariance_yaw>0.010000</covariance_yaw>
        </plugin>
    </gazebo>
    <!-- <xacro:include filename="robot_camera.urdf.xacro"/>
  <xacro:include filename="robot_kinetic.urdf.xacro"/>
  <xacro:include filename="robot_laser.urdf.xacro"/> -->
    <!-- Defining the colors used in this robot -->
    <material name="Black">
        <color rgba="0 0 0 1" />
    </material>
    <material name="White">
        <color rgba="1 1 1 1" />
    </material>
    <material name="Blue">
        <color rgba="0 0 1 1" />
    </material>
    <material name="Red">
        <color rgba="1 0 0 1" />
    </material>
    <!-- ///////////////////////////////////////   bottom_joint   ////////////////////////////////////////// -->
    <joint name="bottom_joint" type="fixed">
        <origin rpy="0 0 0" xyz="0 0 0" />
        <parent link="base_link" />
        <child link="bottom_link" />
    </joint>
    <link name="bottom_link">
        <visual>
            <origin rpy="0 0 0" xyz=" 0 0 -0.02" />
            <geometry>
                <box size="0.1 0.1 0.01" />
            </geometry>
            <material name="Black" />
        </visual>
        <collision>
            <origin rpy="0 0 0" xyz=" 0 0 -0.02" />
            <geometry>
                <box size="0.1 0.1 0.01" />
            </geometry>
        </collision>
        <inertial>
            <mass value="0.1" />
            <inertia ixx="1.0" ixy="0.0" ixz="0.0" iyy="0.5" iyz="0.0" izz="1.0" />
            <origin xyz="0 0 0" rpy="0 0 0" />
        </inertial>
    </link>
    <!-- /////////////////////////////////////   BASE LINK    ////////////////////////////////////////////// -->
    <link name="base_link">
        <visual>
            <origin rpy="0 0 0" xyz="0 0 0" />
            <geometry>
                <box size="0.1 0.1 0.04" />
            </geometry>
            <material name="White" />
        </visual>
        <collision>
            <origin rpy="0 0 0" xyz="0 0 0" />
            <geometry>
                <box size="0.1 0.1 0.04" />
            </geometry>
        </collision>
        <!--<xacro:inertial_matrix mass="1"/>-->
        <inertial>
            <mass value="0.1" />
            <origin xyz="0 0 0" rpy="0 0 0" />
            <inertia ixx="0.03" iyy="0.03" izz="0.03" ixy="0.0" ixz="0.0" iyz="0.0" />
        </inertial>
    </link>
    <joint name="joint1" type="revolute">
        <parent link="base_link" />
        <child link="link1" />
        <origin rpy="0 1.570795 0" xyz="0 0 0.02" />
        <axis xyz="-1 0 0" />
        <limit effort="300" lower="-2.96" upper="2.96" velocity="1" />
        <dynamics damping="50" friction="1" />
    </joint>
    <!-- /////////////////////////////////////   LINK1  ////////////////////////////////////////////// -->
    <link name="link1">
        <visual>
            <origin rpy="0 1.570795 0" xyz="-0.05 0 0" />
            <geometry>
                <cylinder length="0.1" radius="0.03" />
            </geometry>
            <material name="Blue" />
        </visual>
        <collision>
            <origin rpy="0 1.570795 0" xyz="-0.05 0 0" />
            <geometry>
                <cylinder length="0.1" radius="0.03" />
            </geometry>
        </collision>
        <inertial>
            <mass value="0.1" />
            <inertia ixx="1.0" ixy="0.0" ixz="0.0" iyy="0.5" iyz="0.0" izz="1.0" />
            <origin xyz="0 0 0" rpy="0 0 0" />
        </inertial>
    </link>
    <joint name="joint2" type="revolute">
        <parent link="link1" />
        <child link="link2" />
        <origin rpy="-1.570795 0 1.570795" xyz="-0.1 0 0.0" />
        <axis xyz="1 0 0" />
        <limit effort="300" lower="-2.35" upper="2.35" velocity="1" />
        <dynamics damping="50" friction="1" />
    </joint>
    <!-- ///////////////////////////////////////   LINK2  ////////////////////////////////////////////// -->
    <link name="link2">
        <visual>
            <origin rpy="0 0 0" xyz="0 0 0.07" />
            <geometry>
                <cylinder length="0.14" radius="0.03" />
            </geometry>
            <material name="White" />
        </visual>
        <collision>
            <origin rpy="0 0 0" xyz="0 0 0.07" />
            <geometry>
                <cylinder length="0.14" radius="0.03" />
            </geometry>
        </collision>
        <inertial>
            <mass value="0.1" />
            <inertia ixx="1.0" ixy="0.0" ixz="0.0" iyy="0.5" iyz="0.0" izz="1.0" />
            <origin xyz="0 0 0" rpy="0 0 0" />
        </inertial>
    </link>
    <joint name="joint3" type="revolute">
        <parent link="link2" />
        <child link="link3" />
        <origin rpy="0 3.14159 0" xyz="0 0 0.14" />
        <axis xyz="-1 0 0" />
        <limit effort="300" lower="-2.62" upper="2.62" velocity="1" />
        <dynamics damping="50" friction="1" />
    </joint>
    <!-- /////////////////////////////////   LINK3  ///////////////////////////////////////////////////// -->
    <link name="link3">
        <visual>
            <origin rpy="0 0 0" xyz="0 0 -0.11" />
            <geometry>
                <cylinder length="0.22" radius="0.03" />
            </geometry>
            <material name="Blue" />
        </visual>
        <collision>
            <origin rpy="0 0 0" xyz="0 0 -0.11" />
            <geometry>
                <cylinder length="0.22" radius="0.03" />
            </geometry>
        </collision>
        <inertial>
            <mass value="0.1" />
            <inertia ixx="1.0" ixy="0.0" ixz="0.0" iyy="0.5" iyz="0.0" izz="1.0" />
            <origin xyz="0 0 0" rpy="0 0 0" />
        </inertial>
    </link>
    <joint name="joint4" type="revolute">
        <parent link="link3" />
        <child link="link4" />
        <origin rpy="0 1.570795 3.14159" xyz="0.0 0.0 -0.22" />
        <axis xyz="1 0 0" />
        <limit effort="300" lower="-2.62" upper="2.62" velocity="1" />
        <dynamics damping="50" friction="1" />
    </joint>
    <!-- ///////////////////////////////////   LINK4  //////////////////////////////////////////////// -->
    <link name="link4">
        <visual>
            <origin rpy="0 1.570795 0" xyz="0.03 0 0" />
            <geometry>
                <cylinder length="0.06" radius="0.025" />
            </geometry>
            <material name="Black" />
        </visual>
        <collision>
            <origin rpy="0 1.570795 0" xyz="0.03 0 0" />
            <geometry>
                <cylinder length="0.06" radius="0.025" />
            </geometry>
        </collision>
        <inertial>
            <mass value="0.1" />
            <inertia ixx="1.0" ixy="0.0" ixz="0.0" iyy="0.5" iyz="0.0" izz="1.0" />
            <origin xyz="0 0 0" rpy="0 0 0" />
        </inertial>
    </link>
    <joint name="joint5" type="revolute">
        <parent link="link4" />
        <child link="link5" />
        <origin rpy="0 1.570795 0" xyz="0.06 0.0 0.0" />
        <axis xyz="1 0 0" />
        <limit effort="300" lower="-2.62" upper="2.62" velocity="1" />
        <dynamics damping="50" friction="1" />
    </joint>
    <!-- //////////////////////////////////   LINK5  ///////////////////////////////////////////////// -->
    <link name="link5">
        <visual>
            <origin rpy="0 0 0" xyz="0 0 0.03" />
            <geometry>
                <cylinder length="0.06" radius="0.03" />
            </geometry>
            <material name="White" />
        </visual>
        <collision>
            <origin rpy="0 0 0" xyz="0 0 0.03 " />
            <geometry>
                <cylinder length="0.06" radius="0.03" />
            </geometry>
        </collision>
        <inertial>
            <mass value="0.1" />
            <inertia ixx="1.0" ixy="0.0" ixz="0.0" iyy="0.5" iyz="0.0" izz="1.0" />
            <origin xyz="0 0 0" rpy="0 0 0" />
        </inertial>
    </link>
    <joint name="joint6" type="revolute">
        <parent link="link5" />
        <child link="link6" />
        <origin rpy="4.712384999999999 -1.570795 0" xyz="0 0 0.06" />
        <axis xyz="1 0 0" />
        <limit effort="300" lower="-6.28" upper="6.28" velocity="1" />
        <dynamics damping="50" friction="1" />
    </joint>
    <!-- ////////////////////////////////   LINK6  ///////////////////////////////////////////////// -->
    <link name="link6">
        <visual>
            <origin rpy="0 1.570795 0" xyz="0.01 0 0 " />
            <geometry>
                <cylinder length="0.02" radius="0.04" />
            </geometry>
            <material name="Blue" />
        </visual>
        <collision>
            <origin rpy="0 1.570795 0" xyz="0.01 0 0" />
            <geometry>
                <cylinder length="0.02" radius="0.04" />
            </geometry>
        </collision>
        <inertial>
            <mass value="0.1" />
            <inertia ixx="1.0" ixy="0.0" ixz="0.0" iyy="0.5" iyz="0.0" izz="1.0" />
            <origin xyz="0 0 0" rpy="0 0 0" />
        </inertial>
    </link>
    <joint name="finger_joint1" type="prismatic">
        <parent link="link6" />
        <child link="gripper_finger_link1" />
        <origin xyz="0.0 0 0" />
        <axis xyz="0 1 0" />
        <limit effort="100" lower="0" upper="0.06" velocity="1.0" />
        <dynamics damping="50" friction="1" />
    </joint>
    <!-- //////////////////////////////////////   gripper   ////////////////////////////////////////////// -->
    <!-- LEFT GRIPPER AFT LINK -->
    <link name="gripper_finger_link1">
        <visual>
            <origin xyz="0.04 -0.03 0" />
            <geometry>
                <box size="0.08 0.01 0.01" />
            </geometry>
            <material name="White" />
        </visual>
        <collision>
            <origin xyz="0.04 -0.03 0" />
            <geometry>
                <box size="0.08 0.01 0.01" />
            </geometry>
        </collision>
        <inertial>
            <mass value="0.05" />
            <inertia ixx="2.7083333333333335e-05" ixy="0" ixz="0" iyy="2.7083333333333335e-05" iyz="0" izz="8.333333333333334e-07" />
            <origin xyz="0 0 0" rpy="0 0 0" />
        </inertial>
    </link>
    <joint name="finger_joint2" type="fixed">
        <parent link="link6" />
        <child link="gripper_finger_link2" />
        <origin xyz="0.0 0 0" />
    </joint>
    <!-- RIGHT GRIPPER AFT LINK -->
    <link name="gripper_finger_link2">
        <visual>
            <origin xyz="0.04 0.03 0" />
            <geometry>
                <box size="0.08 0.01 0.01" />
            </geometry>
            <material name="White" />
        </visual>
        <collision>
            <origin xyz="0.04 0.03 0" />
            <geometry>
                <box size="0.08 0.01 0.01" />
            </geometry>
        </collision>
        <inertial>
            <mass value="0.05" />
            <inertia ixx="2.7083333333333335e-05" ixy="0" ixz="0" iyy="2.7083333333333335e-05" iyz="0" izz="8.333333333333334e-07" />
            <origin xyz="0 0 0" rpy="0 0 0" />
        </inertial>
    </link>
    <!-- Grasping frame -->
    <link name="grasping_frame" />
    <joint name="grasping_frame_joint" type="fixed">
        <parent link="link6" />
        <child link="grasping_frame" />
        <origin rpy="0 0 0" xyz="0.08 0 0" />
    </joint>
    <!-- /////////////////////////////////   Gazebo   ////////////////////////////////////// -->
    <gazebo reference="base_link">
        <material>Gazebo/White</material>
    </gazebo>
    <gazebo reference="link1">
        <material>Gazebo/Blue</material>
    </gazebo>
    <gazebo reference="link2">
        <material>Gazebo/White</material>
    </gazebo>
    <gazebo reference="link3">
        <material>Gazebo/Blue</material>
    </gazebo>
    <gazebo reference="link4">
        <material>Gazebo/Black</material>
    </gazebo>
    <gazebo reference="link5">
        <material>Gazebo/White</material>
    </gazebo>
    <gazebo reference="link6">
        <material>Gazebo/Blue</material>
    </gazebo>
    <gazebo reference="gripper_finger_link1">
        <material>Gazebo/White</material>
    </gazebo>
    <gazebo reference="gripper_finger_link2">
        <material>Gazebo/White</material>
    </gazebo>
    <transmission name="tran1">
        <type>transmission_interface/SimpleTransmission</type>
        <joint name="joint1">
            <hardwareInterface>hardware_interface/PositionJointInterface</hardwareInterface>
        </joint>
        <actuator name="motor1">
            <hardwareInterface>hardware_interface/PositionJointInterface</hardwareInterface>
            <mechanicalReduction>1</mechanicalReduction>
        </actuator>
    </transmission>
    <transmission name="tran1">
        <type>transmission_interface/SimpleTransmission</type>
        <joint name="joint2">
            <hardwareInterface>hardware_interface/PositionJointInterface</hardwareInterface>
        </joint>
        <actuator name="motor1">
            <hardwareInterface>hardware_interface/PositionJointInterface</hardwareInterface>
            <mechanicalReduction>1</mechanicalReduction>
        </actuator>
    </transmission>
    <transmission name="tran1">
        <type>transmission_interface/SimpleTransmission</type>
        <joint name="joint3">
            <hardwareInterface>hardware_interface/PositionJointInterface</hardwareInterface>
        </joint>
        <actuator name="motor1">
            <hardwareInterface>hardware_interface/PositionJointInterface</hardwareInterface>
            <mechanicalReduction>1</mechanicalReduction>
        </actuator>
    </transmission>
    <transmission name="tran1">
        <type>transmission_interface/SimpleTransmission</type>
        <joint name="joint4">
            <hardwareInterface>hardware_interface/PositionJointInterface</hardwareInterface>
        </joint>
        <actuator name="motor1">
            <hardwareInterface>hardware_interface/PositionJointInterface</hardwareInterface>
            <mechanicalReduction>1</mechanicalReduction>
        </actuator>
    </transmission>
    <transmission name="tran1">
        <type>transmission_interface/SimpleTransmission</type>
        <joint name="joint5">
            <hardwareInterface>hardware_interface/PositionJointInterface</hardwareInterface>
        </joint>
        <actuator name="motor1">
            <hardwareInterface>hardware_interface/PositionJointInterface</hardwareInterface>
            <mechanicalReduction>1</mechanicalReduction>
        </actuator>
    </transmission>
    <transmission name="tran1">
        <type>transmission_interface/SimpleTransmission</type>
        <joint name="joint6">
            <hardwareInterface>hardware_interface/PositionJointInterface</hardwareInterface>
        </joint>
        <actuator name="motor1">
            <hardwareInterface>hardware_interface/PositionJointInterface</hardwareInterface>
            <mechanicalReduction>1</mechanicalReduction>
        </actuator>
    </transmission>
    <transmission name="tran1">
        <type>transmission_interface/SimpleTransmission</type>
        <joint name="finger_joint1">
            <hardwareInterface>hardware_interface/PositionJointInterface</hardwareInterface>
        </joint>
        <actuator name="motor1">
            <hardwareInterface>hardware_interface/PositionJointInterface</hardwareInterface>
            <mechanicalReduction>1</mechanicalReduction>
        </actuator>
    </transmission>
    <!-- ros_control plugin -->
    <gazebo>
        <plugin filename="libgazebo_ros_control.so" name="gazebo_ros_control">
            <robotNamespace>/arm</robotNamespace>
        </plugin>
    </gazebo>
    <joint name="arm2base" type="fixed">
        <origin rpy="0.0 0.0 0.0" xyz="0.0 0.0 0.06" />
        <parent link="robot_base_link" />
        <child link="base_link" />
        <axis xyz="0.0 0.0 0.0" />
        <limit effort="0.0" lower="0.0" upper="0.0" velocity="0.0" />
    </joint>
    <gazebo reference="camera">
        <material>Gazebo/Grey</material>
        <sensor name="camera1" type="camera">
            <update_rate>30.0</update_rate>
            <camera name="head">
                <horizontal_fov>1.3962634</horizontal_fov>
                <image>
                    <width>800</width>
                    <height>800</height>
                    <format>R8G8B8</format>
                </image>
                <clip>
                    <near>0.02</near>
                    <far>300</far>
                </clip>
            </camera>
            <plugin filename="libgazebo_ros_camera.so" name="camera_controller">
                <alwaysOn>true</alwaysOn>
                <updateRate>0.0</updateRate>
                <cameraName>skid_steer_bot/camera1</cameraName>
                <imageTopicName>image_raw</imageTopicName>
                <cameraInfoTopicName>camera_info</cameraInfoTopicName>
                <frameName>camera</frameName>
                <hackBaseline>0.07</hackBaseline>
                <distortionK1>0.0</distortionK1>
                <distortionK2>0.0</distortionK2>
                <distortionK3>0.0</distortionK3>
                <distortionT1>0.0</distortionT1>
                <distortionT2>0.0</distortionT2>
            </plugin>
        </sensor>
    </gazebo>
    <gazebo reference="hokuyo">
        <sensor name="head_hokuyo_sensor" type="ray">
            <pose>0 0 0 0 0 0</pose>
            <visualize>false</visualize>
            <update_rate>40</update_rate>
            <ray>
                <scan>
                    <horizontal>
                        <samples>720</samples>
                        <resolution>1</resolution>
                        <min_angle>-1.570796</min_angle>
                        <max_angle>1.570796</max_angle>
                    </horizontal>
                </scan>
                <range>
                    <min>0.10</min>
                    <max>30.0</max>
                    <resolution>0.01</resolution>
                </range>
                <noise>
                    <type>gaussian</type>
                    <!-- Noise parameters based on published spec for Hokuyo laser
               achieving "+-30mm" accuracy at range < 10m.  A mean of 0.0m and
               stddev of 0.01m will put 99.7% of samples within 0.03m of the true
               reading. -->
                    <mean>0.0</mean>
                    <stddev>0.01</stddev>
                </noise>
            </ray>
            <plugin filename="libgazebo_ros_laser.so" name="gazebo_ros_head_hokuyo_controller">
                <topicName>/skid_steer_bot/laser/scan</topicName>
                <frameName>hokuyo</frameName>
            </plugin>
        </sensor>
    </gazebo>
    <transmission name="trans_left_front_wheel2robot_base_link">
        <type>transmission_interface/SimpleTransmission</type>
        <joint name="left_front_wheel2robot_base_link">
            <hardwareInterface>hardware_interface/EffortJointInterface</hardwareInterface>
        </joint>
        <actuator name="left_front_wheel2robot_base_link_motor">
            <hardwareInterface>hardware_interface/EffortJointInterface</hardwareInterface>
            <mechanicalReduction>1</mechanicalReduction>
        </actuator>
    </transmission>
    <transmission name="trans_right_front_wheel2robot_base_link">
        <type>transmission_interface/SimpleTransmission</type>
        <joint name="right_front_wheel2robot_base_link">
            <hardwareInterface>hardware_interface/EffortJointInterface</hardwareInterface>
        </joint>
        <actuator name="right_front_wheel2robot_base_link_motor">
            <hardwareInterface>hardware_interface/EffortJointInterface</hardwareInterface>
            <mechanicalReduction>1</mechanicalReduction>
        </actuator>
    </transmission>
    <transmission name="trans_left_rear_wheel2robot_base_link">
        <type>transmission_interface/SimpleTransmission</type>
        <joint name="left_rear_wheel2robot_base_link">
            <hardwareInterface>hardware_interface/EffortJointInterface</hardwareInterface>
        </joint>
        <actuator name="left_rear_wheel2robot_base_link_motor">
            <hardwareInterface>hardware_interface/EffortJointInterface</hardwareInterface>
            <mechanicalReduction>1</mechanicalReduction>
        </actuator>
    </transmission>
    <transmission name="trans_right_rear_wheel2robot_base_link">
        <type>transmission_interface/SimpleTransmission</type>
        <joint name="right_rear_wheel2robot_base_link">
            <hardwareInterface>hardware_interface/EffortJointInterface</hardwareInterface>
        </joint>
        <actuator name="right_rear_wheel2robot_base_link_motor">
            <hardwareInterface>hardware_interface/EffortJointInterface</hardwareInterface>
            <mechanicalReduction>1</mechanicalReduction>
        </actuator>
    </transmission>
</robot>

